{
    "track_id": "lzTDPe4c",
    "prompt": "Unknown ERROR->ServerDisconnectedError",
    "time": "2021-12-21 10:57:42",
    "content": "Traceback (most recent call last):\n  File \"C:\\Users\\LazyO\\Desktop\\hokabot\\hoka\\.\\models\\exceptions.py\", line 104, in _track_error\n    raise exception\n  File \"C:\\Users\\LazyO\\AppData\\Local\\Programs\\Python\\Python39\\lib\\site-packages\\nonebot\\message.py\", line 155, in _run_matcher\n    await matcher.run(bot, event, state)\n  File \"C:\\Users\\LazyO\\AppData\\Local\\Programs\\Python\\Python39\\lib\\site-packages\\nonebot\\matcher.py\", line 584, in run\n    await handler(self, bot, event, self.state)\n  File \"C:\\Users\\LazyO\\AppData\\Local\\Programs\\Python\\Python39\\lib\\site-packages\\nonebot\\handler.py\", line 81, in __call__\n    await self.func(\n  File \"C:\\Users\\LazyO\\Desktop\\hokabot\\hoka\\src/plugins\\pic_bank\\__init__.py\", line 32, in _\n    msg = pb.match(await get_pic_from_url(state['img_list'][0]), str(event.group_id))\n  File \"C:\\Users\\LazyO\\Desktop\\hokabot\\hoka\\src/plugins\\pic_bank\\utils.py\", line 38, in get_pic_from_url\n    async with session.get(url, headers=headers) as resp:\n  File \"C:\\Users\\LazyO\\AppData\\Local\\Programs\\Python\\Python39\\lib\\site-packages\\aiohttp\\client.py\", line 1140, in __aenter__\n    self._resp = await self._coro\n  File \"C:\\Users\\LazyO\\AppData\\Local\\Programs\\Python\\Python39\\lib\\site-packages\\aiohttp\\client.py\", line 559, in _request\n    await resp.start(conn)\n  File \"C:\\Users\\LazyO\\AppData\\Local\\Programs\\Python\\Python39\\lib\\site-packages\\aiohttp\\client_reqrep.py\", line 898, in start\n    message, payload = await protocol.read()  # type: ignore[union-attr]\n  File \"C:\\Users\\LazyO\\AppData\\Local\\Programs\\Python\\Python39\\lib\\site-packages\\aiohttp\\streams.py\", line 614, in read\n    await self._waiter\naiohttp.client_exceptions.ServerDisconnectedError: Server disconnected\n"
}