{
    "track_id": "PGxgsNKU",
    "prompt": "Unknown ERROR->TimeoutError",
    "time": "2021-12-21 09:16:54",
    "content": "Traceback (most recent call last):\n  File \"C:\\Users\\LazyO\\Desktop\\hokabot\\hoka\\.\\models\\exceptions.py\", line 104, in _track_error\n    raise exception\n  File \"C:\\Users\\LazyO\\AppData\\Local\\Programs\\Python\\Python39\\lib\\site-packages\\nonebot\\message.py\", line 155, in _run_matcher\n    await matcher.run(bot, event, state)\n  File \"C:\\Users\\LazyO\\AppData\\Local\\Programs\\Python\\Python39\\lib\\site-packages\\nonebot\\matcher.py\", line 584, in run\n    await handler(self, bot, event, self.state)\n  File \"C:\\Users\\LazyO\\AppData\\Local\\Programs\\Python\\Python39\\lib\\site-packages\\nonebot\\handler.py\", line 81, in __call__\n    await self.func(\n  File \"C:\\Users\\LazyO\\Desktop\\hokabot\\hoka\\src/plugins\\pic_bank\\__init__.py\", line 32, in _\n    msg = pb.match(await get_pic_from_url(state['img_list'][0]), str(event.group_id))\n  File \"C:\\Users\\LazyO\\Desktop\\hokabot\\hoka\\src/plugins\\pic_bank\\utils.py\", line 39, in get_pic_from_url\n    return await resp.read()\n  File \"C:\\Users\\LazyO\\AppData\\Local\\Programs\\Python\\Python39\\lib\\site-packages\\aiohttp\\client_reqrep.py\", line 1036, in read\n    self._body = await self.content.read()\n  File \"C:\\Users\\LazyO\\AppData\\Local\\Programs\\Python\\Python39\\lib\\site-packages\\aiohttp\\streams.py\", line 375, in read\n    block = await self.readany()\n  File \"C:\\Users\\LazyO\\AppData\\Local\\Programs\\Python\\Python39\\lib\\site-packages\\aiohttp\\streams.py\", line 397, in readany\n    await self._wait(\"readany\")\n  File \"C:\\Users\\LazyO\\AppData\\Local\\Programs\\Python\\Python39\\lib\\site-packages\\aiohttp\\streams.py\", line 304, in _wait\n    await waiter\n  File \"C:\\Users\\LazyO\\AppData\\Local\\Programs\\Python\\Python39\\lib\\site-packages\\aiohttp\\helpers.py\", line 718, in __exit__\n    raise asyncio.TimeoutError from None\nasyncio.exceptions.TimeoutError\n"
}